<mujoco>
    <option gravity="0 0 -9.81" timestep="0.01" />
    <worldbody>
        <light diffuse=".5 .5 .5" pos="0 0 3" dir="0 0 -1"/>
        <geom type="plane" size="1 1 0.1" rgba=".9 .9 .9 1"/>
        
        <body name="arm" pos="0 0 1.5">
            <joint name="hinge" type="hinge" axis="0 1 0" pos="0 0 0"/>
            <geom name="rod" type="capsule" fromto="0 0 0 0 0 -1" size="0.05" rgba="0 0.7 0.7 1" mass="1.0"/>
        </body>
    </worldbody>

    <actuator>
        <motor joint="hinge" name="torque_control" gear="1" ctrlrange="-10 10" ctrllimited="true"/>
    </actuator>
</mujoco>